<?xml version="1.0"?>
<robot name="my_robot">

  <!-- Constants -->
  <property name="M_PI" value="3.1415926535897931" />
  <property name="M_PI_2" value="1.5707963267948966" />
  <property name="M_PI_4" value="0.7853981633974483" />

  <!-- Materials -->
  <material name="black">
    <color rgba="0.0 0.0 0.0 1.0"/>
  </material>
  <material name="blue">
    <color rgba="0.0 0.0 0.8 1.0"/>
  </material>
  <material name="green">
    <color rgba="0.0 0.8 0.0 1.0"/>
  </material>
  <material name="grey">
    <color rgba="0.2 0.2 0.2 1.0"/>
  </material>
  <material name="orange">
    <color rgba="1.0 0.423529411765 0.0392156862745 1.0"/>
  </material>
  <material name="brown">
    <color rgba="0.870588235294 0.811764705882 0.764705882353 1.0"/>
  </material>
  <material name="red">
    <color rgba="0.8 0.0 0.0 1.0"/>
  </material>
  <material name="white">
    <color rgba="1.0 1.0 1.0 1.0"/>
  </material>

  <!-- Macros -->
  <macro name="box_inertia" params="m x y z">
    <inertia ixx="${m*(y*y+z*z)/12}" ixy="0" ixz="0" iyy="${m*(x*x+z*z)/12}" iyz="0" izz="${m*(x*x+y*y)/12}" />
  </macro>

  <macro name="cylinder_inertia" params="m r h">
    <inertia ixx="${m*(3*r*r+h*h)/12}" ixy="0" ixz="0" iyy="${m*(3*r*r+h*h)/12}" iyz="0" izz="${m*r*r/2}" />
  </macro>

  <macro name="sphere_inertia" params="m r">
    <inertia ixx="${2*m*r*r/5}" ixy="0" ixz="0" iyy="${2*m*r*r/5}" iyz="0" izz="${2*m*r*r/5}" />
  </macro>

  <!-- Main Frame -->
  <link name="main_frame">
    <visual>
      <geometry>
        <box size="0.835 0.8 0.04" />
      </geometry>
      <material name="blue"/>
    </visual>
    <collision>
      <geometry>
        <box size="0.835 0.8 0.04" />
      </geometry>
    </collision>
    <inertial>
      <mass value="10"/>
      <box_inertia m="10" x="0.835" y="0.8" z="0.04"/>
    </inertial>
  </link>

  <!-- Sheet Metal Box -->
  <link name="sheet_metal_box">
    <visual>
      <geometry>
        <box size="0.755 0.72 0.1" />
      </geometry>
      <material name="grey"/>
    </visual>
    <collision>
      <geometry>
        <box size="0.755 0.72 0.1" />
      </geometry>
    </collision>
    <inertial>
      <mass value="5"/>
      <box_inertia m="5" x="0.755" y="0.72" z="0.1"/>
    </inertial>
  </link>

  <joint name="sheet_metal_box_joint" type="fixed">
    <parent link="main_frame"/>
    <child link="sheet_metal_box"/>
    <origin xyz="0 0 -0.05" rpy="0 0 0"/>
  </joint>

  <!-- Back Legs -->
  <link name="back_left_leg">
    <visual>
      <geometry>
        <box size="0.04 0.04 0.5" />
      </geometry>
      <material name="blue"/>
    </visual>
    <collision>
      <geometry>
        <box size="0.04 0.04 0.5" />
      </geometry>
    </collision>
    <inertial>
      <mass value="1"/>
      <box_inertia m="1" x="0.04" y="0.04" z="0.5"/>
    </inertial>
  </link>

  <joint name="back_left_leg_joint" type="fixed">
    <parent link="main_frame"/>
    <child link="back_left_leg"/>
    <origin xyz="-0.3975 0.38 0" rpy="0 0 0"/>
  </joint>

  <link name="back_right_leg">
    <visual>
      <geometry>
        <box size="0.04 0.04 0.5" />
      </geometry>
      <material name="blue"/>
    </visual>
    <collision>
      <geometry>
        <box size="0.04 0.04 0.5" />
      </geometry>
    </collision>
    <inertial>
      <mass value="1"/>
      <box_inertia m="1" x="0.04" y="0.04" z="0.5"/>
    </inertial>
  </link>

  <joint name="back_right_leg_joint" type="fixed">
    <parent link="main_frame"/>
    <child link="back_right_leg"/>
    <origin xyz="-0.3975 -0.38 0" rpy="0 0 0"/>
  </joint>

  <!-- Pivoting Section -->
  <link name="pivot_section">
    <visual>
      <geometry>
        <box size="0.8 0.04 0.04" />
      </geometry>
      <material name="red"/>
    </visual>
    <collision>
      <geometry>
        <box size="0.8 0.04 0.04" />
      </geometry>
    </collision>
    <inertial>
      <mass value="5"/>
      <box_inertia m="5" x="0.8" y="0.04" z="0.04"/>
    </inertial>
  </link>

  <joint name="pivot_joint" type="revolute">
    <parent link="main_frame"/>
    <child link="pivot_section"/>
    <origin xyz="0 0 0" rpy="0 0 0"/>
    <axis xyz="0 1 0"/>
    <limit lower="-${M_PI_4}" upper="${M_PI_4}" effort="10" velocity="1.0"/>
  </joint>

  <!-- Front Legs -->
  <link name="front_left_leg">
    <visual>
      <geometry>
        <box size="0.04 0.04 0.5" />
      </geometry>
      <material name="red"/>
    </visual>
    <collision>
      <geometry>
        <box size="0.04 0.04 0.5" />
      </geometry>
    </collision>
    <inertial>
      <mass value="1"/>
      <box_inertia m="1" x="0.04" y="0.04" z="0.5"/>
    </inertial>
  </link>

  <joint name="front_left_leg_joint" type="fixed">
    <parent link="pivot_section"/>
    <child link="front_left_leg"/>
    <origin xyz="0.38 0 0" rpy="0 0 0"/>
  </joint>

  <link name="front_right_leg">
    <visual>
      <geometry>
        <box size="0.04 0.04 0.5" />
      </geometry>
      <material name="red"/>
    </visual>
    <collision>
      <geometry>
        <box size="0.04 0.04 0.5" />
      </geometry>
    </collision>
    <inertial>
      <mass value="1"/>
      <box_inertia m="1" x="0.04" y="0.04" z="0.5"/>
    </inertial>
  </link>

  <joint name="front_right_leg_joint" type="fixed">
    <parent link="pivot_section"/>
    <child link="front_right_leg"/>
    <origin xyz="-0.38 0 0" rpy="0 0 0"/>
  </joint>

  <!-- Wheels -->
  <macro name="wheel" params="prefix parent x y z">
    <link name="${prefix}_wheel">
      <visual>
        <origin xyz="0 0 0" rpy="${M_PI_2} 0 0"/>
        <geometry>
          <cylinder radius="0.15" length="0.11"/>
        </geometry>
        <material name="black"/>
      </visual>
      <collision>
        <origin xyz="0 0 0" rpy="${M_PI_2} 0 0"/>
        <geometry>
          <cylinder radius="0.15" length="0.11"/>
        </geometry>
      </collision>
      <inertial>
        <mass value="2"/>
        <cylinder_inertia m="2" r="0.15" h="0.11"/>
      </inertial>
    </link>

    <joint name="${prefix}_wheel_joint" type="revolute">
      <parent link="${parent}"/>
      <child link="${prefix}_wheel"/>
      <origin xyz="${x} ${y} ${z}" rpy="0 0 0"/>
      <axis xyz="0 1 0"/>
      <limit lower="-10000" upper="10000" effort="10" velocity="10"/>
    </joint>
  </macro>

  <wheel prefix="back_left" parent="back_left_leg" x="0" y="0.08" z="-0.215"/>
  <wheel prefix="back_right" parent="back_right_leg" x="0" y="-0.08" z="-0.215"/>
  <wheel prefix="front_left" parent="front_left_leg" x="0" y="0.08" z="-0.215"/>
  <wheel prefix="front_right" parent="front_right_leg" x="0" y="-0.08" z="-0.215"/>

</robot>
